Workbook

Sheet Tennessee counties
A1: county | B1: 1900 population | C1: 1910 | D1: 1920 | E1: 1930 | F1: 1940 | G1: 1950 | H1: 1960
A2: Anderson | B2: 17634 | C2: 17717 | D2: 18298 | E2: 19722 | F2: 26504 | G2: 59407 | H2: 60032
A3: Bedford | B3: 23845 | C3: 22667 | D3: 21737 | E3: 21077 | F3: 23151 | G3: 23627 | H3: 23150
A4: Benton | B4: 11888 | C4: 12452 | D4: 12046 | E4: 11237 | F4: 11976 | G4: 11495 | H4: 10662
A5: Bledsoe | B5: 6626 | C5: 6329 | D5: 7218 | E5: 7128 | F5: 8358 | G5: 8561 | H5: 7811
A6: Blount | B6: 19206 | C6: 20809 | D6: 28800 | E6: 33989 | F6: 41116 | G6: 54691 | H6: 57525
A7: Bradley | B7: 15759 | C7: 16336 | D7: 18652 | E7: 22870 | F7: 28498 | G7: 32338 | H7: 38324
A8: Campbell | B8: 17317 | C8: 27387 | D8: 28265 | E8: 26827 | F8: 31131 | G8: 34369 | H8: 27936
A9: Cannon | B9: 12121 | C9: 10825 | D9: 10241 | E9: 8935 | F9: 9880 | G9: 9174 | H9: 8537
A10: Carroll | B10: 24250 | C10: 23971 | D10: 24361 | E10: 26132 | F10: 25978 | G10: 26553 | H10: 23476
A11: Carter | B11: 16688 | C11: 19838 | D11: 21488 | E11: 29223 | F11: 35127 | G11: 42432 | H11: 41578
A12: Cheatham | B12: 10112 | C12: 10540 | D12: 10039 | E12: 9025 | F12: 9928 | G12: 9167 | H12: 9428
A13: Chester | B13: 9896 | C13: 9090 | D13: 9669 | E13: 10603 | F13: 11124 | G13: 11149 | H13: 9569
... A33: Hamblen | B33: 12728 | C33: 13650 | D33: 15056 | E33: 16616 | F33: 18611 | G33: 23976 | H33: 33092
A34: Hamilton | B34: =61695+5407 -> 67102 | C34: =89267+5210 -> 94477 | D34: 115954 | E34: 159497 | F34: 180478 | G34: 208255 | H34: 237905
A35: Hancock | B35: 11147 | C35: 10778 | D35: 10454 | E35: 9673 | F35: 11231 | G35: 9116 | H35: 7757
A36: Hardeman | B36: 22976 | C36: 23011 | D36: 22278 | E36: 22193 | F36: 23590 | G36: 23311 | H36: 21517
A37: Hardin | B37: 19246 | C37: 17521 | D37: 17291 | E37: 16213 | F37: 17806 | G37: 16908 | H37: 17397
A38: Hawkins | B38: 24267 | C38: 23587 | D38: 22918 | E38: 24117 | F38: 28523 | G38: 30494 | H38: 30468
A39: Haywood | B39: 25189 | C39: 25910 | D39: 25386 | E39: 26063 | F39: 27699 | G39: 26212 | H39: 23393
A40: Henderson | B40: 18117 | C40: 17030 | D40: 18436 | E40: 17655 | F40: 19220 | G40: 17173 | H40: 16115
A41: Henry | B41: 24208 | C41: 25434 | D41: 27151 | E41: 26432 | F41: 25877 | G41: 23828 | H41: 22275
A42: Hickman | B42: 16367 | C42: 16527 | D42: 16216 | E42: 13613 | F42: 14873 | G42: 13353 | H42: 11862
A43: Houston | B43: 6476 | C43: 6224 | D43: 6212 | E43: 5555 | F43: 6432 | G43: 5318 | H43: 4794
A44: Humphreys | B44: 13398 | C44: 13908 | D44: 13482 | E44: 12039 | F44: 12421 | G44: 11030 | H44: 11511
A45: Jackson | B45: 15039 | C45: 15036 | D45: 14955 | E45: 13589 | F45: 15082 | G45: 12348 | H45: 9233
A46: Jefferson | B46: 18590 | C46: 17755 | D46: 17677 | E46: 17914 | F46: 18621 | G46: 19667 | H46: 21493
... A96: Wilson | B96: 27078 | C96: 25394 | D96: 26241 | E96: 23929 | F96: 25267 | G96: 26318 | H96: 27668
C98: Note James county was abolished in 1919 and merged with Hamilton County. James population is added to Hamilton in 1900 and 1910 in this table.

Sheet House districts
A1: county | B1: seats | C1: 1900 population | D1: ideal population | E1: deviation | F1: 1910 | G1: ideal population | H1: deviation | I1: 1920 | J1: ideal population | K1: deviation | L1: 1930 | M1: ideal population | N1: deviation | O1: 1940 | P1: ideal population | Q1: deviation | R1: 1950 | S1: ideal population | T1: deviation | U1: 1960 | V1: ideal population | W1: deviation
A2: Bedford | B2: 1 | C2: ='Tennessee counties'!B3 -> 23845 | D2: =SUM('Tennessee counties'!B2:B96)/99 -> 20410.263 | E2: =C2-D2 -> 3434.7374 | F2: ='Tennessee counties'!C3 -> 22667 | G2: =SUM('Tennessee counties'!C2:C96)/99 -> 22068.576 | H2: =F2-G2 -> 598.42424 | I2: ='Tennessee counties'!D3 -> 21737 | J2: =SUM('Tennessee counties'!D2:D96)/99 -> 23615 | K2: =I2-J2 -> -1878 | L2: ='Tennessee counties'!E3 -> 21077 | M2: =SUM('Tennessee counties'!E2:E96)/99 -> 26429.859 | N2: =L2-M2 -> -5352.8586 | O2: ='Tennessee counties'!F3 -> 23151 | P2: =SUM('Tennessee counties'!F2:F96)/99 -> 29452.939 | Q2: =O2-P2 -> -6301.9394 | R2: ='Tennessee counties'!G3 -> 23627 | S2: =SUM('Tennessee counties'!G2:G96)/99 -> 33249.677 | T2: =R2-S2 -> -9622.6768 | U2: ='Tennessee counties'!H3 -> 23150 | V2: =SUM('Tennessee counties'!H2:H96)/99 -> 36031.202 | W2: =U2-V2 -> -12881.202
A3: Blount | B3: 1 | C3: ='Tennessee counties'!B4 -> 11888 | D3: =$D$2 -> 20410.263 | E3: =C3-D3 -> -8522.2626 | F3: ='Tennessee counties'!C4 -> 12452 | G3: =$G$2 -> 22068.576 | H3: =F3-G3 -> -9616.5758 | I3: ='Tennessee counties'!D6 -> 28800 | J3: =$J$2 -> 23615 | K3: =I3-J3 -> 5185 | L3: ='Tennessee counties'!E6 -> 33989 | M3: =$M$2 -> 26429.859 | N3: =L3-M3 -> 7559.1414 | O3: ='Tennessee counties'!F6 -> 41116 | P3: =$P$2 -> 29452.939 | Q3: =O3-P3 -> 11663.061 | R3: ='Tennessee counties'!G6 -> 54691 | S3: =$S$2 -> 33249.677 | T3: =R3-S3 -> 21441.323 | U3: ='Tennessee counties'!H6 -> 57525 | V3: =$V$2 -> 36031.202 | W3: =U3-V3 -> 21493.798
A4: Cannon | B4: 1 | C4: ='Tennessee counties'!B5 -> 6626 | D4: =$D$2 -> 20410.263 | E4: =C4-D4 -> -13784.263 | F4: ='Tennessee counties'!C5 -> 6329 | G4: =$G$2 -> 22068.576 | H4: =F4-G4 -> -15739.576 | I4: ='Tennessee counties'!D9 -> 10241 | J4: =$J$2 -> 23615 | K4: =I4-J4 -> -13374 | L4: ='Tennessee counties'!E9 -> 8935 | M4: =$M$2 -> 26429.859 | N4: =L4-M4 -> -17494.859 | O4: ='Tennessee counties'!F9 -> 9880 | P4: =$P$2 -> 29452.939 | Q4: =O4-P4 -> -19572.939 | R4: ='Tennessee counties'!G9 -> 9174 | S4: =$S$2 -> 33249.677 | T4: =R4-S4 -> -24075.677 | U4: ='Tennessee counties'!H9 -> 8537 | V4: =$V$2 -> 36031.202 | W4: =U4-V4 -> -27494.202
A5: Carroll | B5: 1 | C5: ='Tennessee counties'!B6 -> 19206 | D5: =$D$2 -> 20410.263 | E5: =C5-D5 -> -1204.2626 | F5: ='Tennessee counties'!C6 -> 20809 | G5: =$G$2 -> 22068.576 | H5: =F5-G5 -> -1259.5758 | I5: ='Tennessee counties'!D10 -> 24361 | J5: =$J$2 -> 23615 | K5: =I5-J5 -> 746 | L5: ='Tennessee counties'!E10 -> 26132 | M5: =$M$2 -> 26429.859 | N5: =L5-M5 -> -297.85859 | O5: ='Tennessee counties'!F10 -> 25978 | P5: =$P$2 -> 29452.939 | Q5: =O5-P5 -> -3474.9394 | R5: ='Tennessee counties'!G10 -> 26553 | S5: =$S$2 -> 33249.677 | T5: =R5-S5 -> -6696.6768 | U5: ='Tennessee counties'!H10 -> 23476 | V5: =$V$2 -> 36031.202 | W5: =U5-V5 -> -12555.202
A6: Chester | B6: 1 | C6: ='Tennessee counties'!B7 -> 15759 | D6: =$D$2 -> 20410.263 | E6: =C6-D6 -> -4651.2626 | F6: ='Tennessee counties'!C7 -> 16336 | G6: =$G$2 -> 22068.576 | H6: =F6-G6 -> -5732.5758 | I6: ='Tennessee counties'!D13 -> 9669 | J6: =$J$2 -> 23615 | K6: =I6-J6 -> -13946 | L6: ='Tennessee counties'!E13 -> 10603 | M6: =$M$2 -> 26429.859 | N6: =L6-M6 -> -15826.859 | O6: ='Tennessee counties'!F13 -> 11124 | P6: =$P$2 -> 29452.939 | Q6: =O6-P6 -> -18328.939 | R6: ='Tennessee counties'!G13 -> 11149 | S6: =$S$2 -> 33249.677 | T6: =R6-S6 -> -22100.677 | U6: ='Tennessee counties'!H13 -> 9569 | V6: =$V$2 -> 36031.202 | W6: =U6-V6 -> -26462.202
A7: Cocke | B7: 1 | C7: ='Tennessee counties'!B8 -> 17317 | D7: =$D$2 -> 20410.263 | E7: =C7-D7 -> -3093.2626 | F7: ='Tennessee counties'!C8 -> 27387 | G7: =$G$2 -> 22068.576 | H7: =F7-G7 -> 5318.4242 | I7: ='Tennessee counties'!D16 -> 20782 | J7: =$J$2 -> 23615 | K7: =I7-J7 -> -2833 | L7: ='Tennessee counties'!E16 -> 21775 | M7: =$M$2 -> 26429.859 | N7: =L7-M7 -> -4654.8586 | O7: ='Tennessee counties'!F16 -> 24083 | P7: =$P$2 -> 29452.939 | Q7: =O7-P7 -> -5369.9394 | R7: ='Tennessee counties'!G16 -> 22991 | S7: =$S$2 -> 33249.677 | T7: =R7-S7 -> -10258.677 | U7: ='Tennessee counties'!H16 -> 23390 | V7: =$V$2 -> 36031.202 | W7: =U7-V7 -> -12641.202
A8: Claiborne | B8: 1 | C8: ='Tennessee counties'!B9 -> 12121 | D8: =$D$2 -> 20410.263 | E8: =C8-D8 -> -8289.2626 | F8: ='Tennessee counties'!C9 -> 10825 | G8: =$G$2 -> 22068.576 | H8: =F8-G8 -> -11243.576 | I8: ='Tennessee counties'!D14 -> 23286 | J8: =$J$2 -> 23615 | K8: =I8-J8 -> -329 | L8: ='Tennessee counties'!E14 -> 24313 | M8: =$M$2 -> 26429.859 | N8: =L8-M8 -> -2116.8586 | O8: ='Tennessee counties'!F14 -> 24657 | P8: =$P$2 -> 29452.939 | Q8: =O8-P8 -> -4795.9394 | R8: ='Tennessee counties'!G14 -> 24788 | S8: =$S$2 -> 33249.677 | T8: =R8-S8 -> -8461.6768 | U8: ='Tennessee counties'!H14 -> 19067 | V8: =$V$2 -> 36031.202 | W8: =U8-V8 -> -16964.202
A9: Coffee | B9: 1 | C9: ='Tennessee counties'!B10 -> 24250 | D9: =$D$2 -> 20410.263 | E9: =C9-D9 -> 3839.7374 | F9: ='Tennessee counties'!C10 -> 23971 | G9: =$G$2 -> 22068.576 | H9: =F9-G9 -> 1902.4242 | I9: ='Tennessee counties'!D17 -> 17344 | J9: =$J$2 -> 23615 | K9: =I9-J9 -> -6271 | L9: ='Tennessee counties'!E17 -> 16801 | M9: =$M$2 -> 26429.859 | N9: =L9-M9 -> -9628.8586 | O9: ='Tennessee counties'!F17 -> 18959 | P9: =$P$2 -> 29452.939 | Q9: =O9-P9 -> -10493.939 | R9: ='Tennessee counties'!G17 -> 23049 | S9: =$S$2 -> 33249.677 | T9: =R9-S9 -> -10200.677 | U9: ='Tennessee counties'!H17 -> 28603 | V9: =$V$2 -> 36031.202 | W9: =U9-V9 -> -7428.202
A10: Crockett | B10: 1 | C10: ='Tennessee counties'!B11 -> 16688 | D10: =$D$2 -> 20410.263 | E10: =C10-D10 -> -3722.2626 | F10: ='Tennessee counties'!C11 -> 19838 | G10: =$G$2 -> 22068.576 | H10: =F10-G10 -> -2230.5758 | I10: ='Tennessee counties'!D18 -> 17438 | J10: =$J$2 -> 23615 | K10: =I10-J10 -> -6177 | L10: ='Tennessee counties'!E18 -> 17359 | M10: =$M$2 -> 26429.859 | N10: =L10-M10 -> -9070.8586 | O10: ='Tennessee counties'!F18 -> 17330 | P10: =$P$2 -> 29452.939 | Q10: =O10-P10 -> -12122.939 | R10: ='Tennessee counties'!G18 -> 16624 | S10: =$S$2 -> 33249.677 | T10: =R10-S10 -> -16625.677 | U10: ='Tennessee counties'!H18 -> 14594 | V10: =$V$2 -> 36031.202 | W10: =U10-V10 -> -21437.202
A11: DeKalb | B11: 1 | C11: ='Tennessee counties'!B12 -> 10112 | D11: =$D$2 -> 20410.263 | E11: =C11-D11 -> -10298.263 | F11: ='Tennessee counties'!C12 -> 10540 | G11: =$G$2 -> 22068.576 | H11: =F11-G11 -> -11528.576 | I11: ='Tennessee counties'!D22 -> 15370 | J11: =$J$2 -> 23615 | K11: =I11-J11 -> -8245 | L11: ='Tennessee counties'!E22 -> 14213 | M11: =$M$2 -> 26429.859 | N11: =L11-M11 -> -12216.859 | O11: ='Tennessee counties'!F22 -> 14588 | P11: =$P$2 -> 29452.939 | Q11: =O11-P11 -> -14864.939 | R11: ='Tennessee counties'!G22 -> 11680 | S11: =$S$2 -> 33249.677 | T11: =R11-S11 -> -21569.677 | U11: ='Tennessee counties'!H22 -> 10774 | V11: =$V$2 -> 36031.202 | W11: =U11-V11 -> -25257.202
A12: Dickson | B12: 1 | C12: ='Tennessee counties'!B13 -> 9896 | D12: =$D$2 -> 20410.263 | E12: =C12-D12 -> -10514.263 | F12: ='Tennessee counties'!C13 -> 9090 | G12: =$G$2 -> 22068.576 | H12: =F12-G12 -> -12978.576 | I12: ='Tennessee counties'!D23 -> 19342 | J12: =$J$2 -> 23615 | K12: =I12-J12 -> -4273 | L12: ='Tennessee counties'!E23 -> 18491 | M12: =$M$2 -> 26429.859 | N12: =L12-M12 -> -7938.8586 | O12: ='Tennessee counties'!F23 -> 19718 | P12: =$P$2 -> 29452.939 | Q12: =O12-P12 -> -9734.9394 | R12: ='Tennessee counties'!G23 -> 18805 | S12: =$S$2 -> 33249.677 | T12: =R12-S12 -> -14444.677 | U12: ='Tennessee counties'!H23 -> 18839 | V12: =$V$2 -> 36031.202 | W12: =U12-V12 -> -17192.202
A13: Dyer | B13: 1 | C13: ='Tennessee counties'!B14 -> 20696 | D13: =$D$2 -> 20410.263 | E13: =C13-D13 -> 285.73737 | F13: ='Tennessee counties'!C14 -> 23504 | G13: =$G$2 -> 22068.576 | H13: =F13-G13 -> 1435.4242 | I13: ='Tennessee counties'!D24 -> 29983 | J13: =$J$2 -> 23615 | K13: =I13-J13 -> 6368 | L13: ='Tennessee counties'!E24 -> 31405 | M13: =$M$2 -> 26429.859 | N13: =L13-M13 -> 4975.1414 | O13: ='Tennessee counties'!F24 -> 34920 | P13: =$P$2 -> 29452.939 | Q13: =O13-P13 -> 5467.0606 | R13: ='Tennessee counties'!G24 -> 33473 | S13: =$S$2 -> 33249.677 | T13: =R13-S13 -> 223.32323 | U13: ='Tennessee counties'!H24 -> 29537 | V13: =$V$2 -> 36031.202 | W13: =U13-V13 -> -6494.202
A14: Fayette | B14: 1 | C14: ='Tennessee counties'!B15 -> 8421 | D14: =$D$2 -> 20410.263 | E14: =C14-D14 -> -11989.263 | F14: ='Tennessee counties'!C15 -> 9009 | G14: =$G$2 -> 22068.576 | H14: =F14-G14 -> -13059.576 | I14: ='Tennessee counties'!D25 -> 31499 | J14: =$J$2 -> 23615 | K14: =I14-J14 -> 7884 | L14: ='Tennessee counties'!E25 -> 28891 | M14: =$M$2 -> 26429.859 | N14: =L14-M14 -> 2461.1414 | O14: ='Tennessee counties'!F25 -> 30322 | P14: =$P$2 -> 29452.939 | Q14: =O14-P14 -> 869.06061 | R14: ='Tennessee counties'!G25 -> 27535 | S14: =$S$2 -> 33249.677 | T14: =R14-S14 -> -5714.6768 | U14: ='Tennessee counties'!H25 -> 24577 | V14: =$V$2 -> 36031.202 | W14: =U14-V14 -> -11454.202
A15: Franklin | B15: 1 | C15: ='Tennessee counties'!B16 -> 19153 | D15: =$D$2 -> 20410.263 | E15: =C15-D15 -> -1257.2626 | F15: ='Tennessee counties'!C16 -> 19399 | G15: =$G$2 -> 22068.576 | H15: =F15-G15 -> -2669.5758 | I15: ='Tennessee counties'!D27 -> 20641 | J15: =$J$2 -> 23615 | K15: =I15-J15 -> -2974 | L15: ='Tennessee counties'!E27 -> 21796 | M15: =$M$2 -> 26429.859 | N15: =L15-M15 -> -4633.8586 | O15: ='Tennessee counties'!F27 -> 23892 | P15: =$P$2 -> 29452.939 | Q15: =O15-P15 -> -5560.9394 | R15: ='Tennessee counties'!G27 -> 25431 | S15: =$S$2 -> 33249.677 | T15: =R15-S15 -> -7818.6768 | U15: ='Tennessee counties'!H27 -> 25528 | V15: =$V$2 -> 36031.202 | W15: =U15-V15 -> -10503.202
A16: Giles | B16: 1 | C16: ='Tennessee counties'!B17 -> 15574 | D16: =$D$2 -> 20410.263 | E16: =C16-D16 -> -4836.2626 | F16: ='Tennessee counties'!C17 -> 15625 | G16: =$G$2 -> 22068.576 | H16: =F16-G16 -> -6443.5758 | I16: ='Tennessee counties'!D29 -> 30948 | J16: =$J$2 -> 23615 | K16: =I16-J16 -> 7333 | L16: ='Tennessee counties'!E29 -> 28016 | M16: =$M$2 -> 26429.859 | N16: =L16-M16 -> 1586.1414 | O16: ='Tennessee counties'!F29 -> 29240 | P16: =$P$2 -> 29452.939 | Q16: =O16-P16 -> -212.93939 | R16: ='Tennessee counties'!G29 -> 26961 | S16: =$S$2 -> 33249.677 | T16: =R16-S16 -> -6288.6768 | U16: ='Tennessee counties'!H29 -> 22410 | V16: =$V$2 -> 36031.202 | W16: =U16-V16 -> -13621.202
A17: Greene | B17: 1 | C17: ='Tennessee counties'!B18 -> 15867 | D17: =$D$2 -> 20410.263 | E17: =C17-D17 -> -4543.2626 | F17: ='Tennessee counties'!C18 -> 16076 | G17: =$G$2 -> 22068.576 | H17: =F17-G17 -> -5992.5758 | I17: ='Tennessee counties'!D31 -> 32824 | J17: =$J$2 -> 23615 | K17: =I17-J17 -> 9209 | L17: ='Tennessee counties'!E31 -> 35119 | M17: =$M$2 -> 26429.859 | N17: =L17-M17 -> 8689.1414 | O17: ='Tennessee counties'!F31 -> 39405 | P17: =$P$2 -> 29452.939 | Q17: =O17-P17 -> 9952.0606 | R17: ='Tennessee counties'!G31 -> 41048 | S17: =$S$2 -> 33249.677 | T17: =R17-S17 -> 7798.3232 | U17: ='Tennessee counties'!H31 -> 42163 | V17: =$V$2 -> 36031.202 | W17: =U17-V17 -> 6131.798
A18: Hardeman | B18: 1 | C18: ='Tennessee counties'!B19 -> 8311 | D18: =$D$2 -> 20410.263 | E18: =C18-D18 -> -12099.263 | F18: ='Tennessee counties'!C19 -> 9327 | G18: =$G$2 -> 22068.576 | H18: =F18-G18 -> -12741.576 | I18: ='Tennessee counties'!D36 -> 22278 | J18: =$J$2 -> 23615 | K18: =I18-J18 -> -1337 | L18: ='Tennessee counties'!E36 -> 22193 | M18: =$M$2 -> 26429.859 | N18: =L18-M18 -> -4236.8586 | O18: ='Tennessee counties'!F36 -> 23590 | P18: =$P$2 -> 29452.939 | Q18: =O18-P18 -> -5862.9394 | R18: ='Tennessee counties'!G36 -> 23311 | S18: =$S$2 -> 33249.677 | T18: =R18-S18 -> -9938.6768 | U18: ='Tennessee counties'!H36 -> 21517 | V18: =$V$2 -> 36031.202 | W18: =U18-V18 -> -14514.202
A19: Hardin | B19: 1 | C19: ='Tennessee counties'!B20 -> 122815 | D19: =$D$2 -> 20410.263 | E19: =C19-D19 -> 102404.74 | F19: ='Tennessee counties'!C20 -> 149478 | G19: =$G$2 -> 22068.576 | H19: =F19-G19 -> 127409.42 | I19: ='Tennessee counties'!D37 -> 17291 | J19: =$J$2 -> 23615 | K19: =I19-J19 -> -6324 | L19: ='Tennessee counties'!E37 -> 16213 | M19: =$M$2 -> 26429.859 | N19: =L19-M19 -> -10216.859 | O19: ='Tennessee counties'!F37 -> 17806 | P19: =$P$2 -> 29452.939 | Q19: =O19-P19 -> -11646.939 | R19: ='Tennessee counties'!G37 -> 16908 | S19: =$S$2 -> 33249.677 | T19: =R19-S19 -> -16341.677 | U19: ='Tennessee counties'!H37 -> 17397 | V19: =$V$2 -> 36031.202 | W19: =U19-V19 -> -18634.202
A20: Henry | B20: 1 | C20: ='Tennessee counties'!B21 -> 10439 | D20: =$D$2 -> 20410.263 | E20: =C20-D20 -> -9971.2626 | F20: ='Tennessee counties'!C21 -> 10093 | G20: =$G$2 -> 22068.576 | H20: =F20-G20 -> -11975.576 | I20: ='Tennessee counties'!D41 -> 27151 | J20: =$J$2 -> 23615 | K20: =I20-J20 -> 3536 | L20: ='Tennessee counties'!E41 -> 26432 | M20: =$M$2 -> 26429.859 | N20: =L20-M20 -> 2.1414141 | O20: ='Tennessee counties'!F41 -> 25877 | P20: =$P$2 -> 29452.939 | Q20: =O20-P20 -> -3575.9394 | R20: ='Tennessee counties'!G41 -> 23828 | S20: =$S$2 -> 33249.677 | T20: =R20-S20 -> -9421.6768 | U20: ='Tennessee counties'!H41 -> 22275 | V20: =$V$2 -> 36031.202 | W20: =U20-V20 -> -13756.202
A21: Hickman | B21: 1 | C21: ='Tennessee counties'!B22 -> 16460 | D21: =$D$2 -> 20410.263 | E21: =C21-D21 -> -3950.2626 | F21: ='Tennessee counties'!C22 -> 15434 | G21: =$G$2 -> 22068.576 | H21: =F21-G21 -> -6634.5758 | I21: ='Tennessee counties'!D42 -> 16216 | J21: =$J$2 -> 23615 | K21: =I21-J21 -> -7399 | L21: ='Tennessee counties'!E42 -> 13613 | M21: =$M$2 -> 26429.859 | N21: =L21-M21 -> -12816.859 | O21: ='Tennessee counties'!F42 -> 14873 | P21: =$P$2 -> 29452.939 | Q21: =O21-P21 -> -14579.939 | R21: ='Tennessee counties'!G42 -> 13353 | S21: =$S$2 -> 33249.677 | T21: =R21-S21 -> -19896.677 | U21: ='Tennessee counties'!H42 -> 11862 | V21: =$V$2 -> 36031.202 | W21: =U21-V21 -> -24169.202
A22: Hawkins | B22: 1 | C22: ='Tennessee counties'!B23 -> 18635 | D22: =$D$2 -> 20410.263 | E22: =C22-D22 -> -1775.2626 | F22: ='Tennessee counties'!C23 -> 19955 | G22: =$G$2 -> 22068.576 | H22: =F22-G22 -> -2113.5758 | I22: ='Tennessee counties'!D38 -> 22918 | J22: =$J$2 -> 23615 | K22: =I22-J22 -> -697 | L22: ='Tennessee counties'!E38 -> 24117 | M22: =$M$2 -> 26429.859 | N22: =L22-M22 -> -2312.8586 | O22: ='Tennessee counties'!F38 -> 28523 | P22: =$P$2 -> 29452.939 | Q22: =O22-P22 -> -929.93939 | R22: ='Tennessee counties'!G38 -> 30494 | S22: =$S$2 -> 33249.677 | T22: =R22-S22 -> -2755.6768 | U22: ='Tennessee counties'!H38 -> 30468 | V22: =$V$2 -> 36031.202 | W22: =U22-V22 -> -5563.202
A23: Haywood | B23: 1 | C23: ='Tennessee counties'!B24 -> 23776 | D23: =$D$2 -> 20410.263 | E23: =C23-D23 -> 3365.7374 | F23: ='Tennessee counties'!C24 -> 27721 | G23: =$G$2 -> 22068.576 | H23: =F23-G23 -> 5652.4242 | I23: ='Tennessee counties'!D39 -> 25386 | J23: =$J$2 -> 23615 | K23: =I23-J23 -> 1771 | L23: ='Tennessee counties'!E39 -> 26063 | M23: =$M$2 -> 26429.859 | N23: =L23-M23 -> -366.85859 | O23: ='Tennessee counties'!F39 -> 27699 | P23: =$P$2 -> 29452.939 | Q23: =O23-P23 -> -1753.9394 | R23: ='Tennessee counties'!G39 -> 26212 | S23: =$S$2 -> 33249.677 | T23: =R23-S23 -> -7037.6768 | U23: ='Tennessee counties'!H39 -> 23393 | V23: =$V$2 -> 36031.202 | W23: =U23-V23 -> -12638.202
A24: Jackson | B24: 1 | C24: ='Tennessee counties'!B25 -> 29701 | D24: =$D$2 -> 20410.263 | E24: =C24-D24 -> 9290.7374 | F24: ='Tennessee counties'!C25 -> 30257 | G24: =$G$2 -> 22068.576 | H24: =F24-G24 -> 8188.4242 | I24: ='Tennessee counties'!D45 -> 14955 | J24: =$J$2 -> 23615 | K24: =I24-J24 -> -8660 | L24: ='Tennessee counties'!E45 -> 13589 | M24: =$M$2 -> 26429.859 | N24: =L24-M24 -> -12840.859 | O24: ='Tennessee counties'!F45 -> 15082 | P24: =$P$2 -> 29452.939 | Q24: =O24-P24 -> -14370.939 | R24: ='Tennessee counties'!G45 -> 12348 | S24: =$S$2 -> 33249.677 | T24: =R24-S24 -> -20901.677 | U24: ='Tennessee counties'!H45 -> 9233 | V24: =$V$2 -> 36031.202 | W24: =U24-V24 -> -26798.202
A25: Lake | B25: 1 | C25: ='Tennessee counties'!B26 -> 6106 | D25: =$D$2 -> 20410.263 | E25: =C25-D25 -> -14304.263 | F25: ='Tennessee counties'!C26 -> 7446 | G25: =$G$2 -> 22068.576 | H25: =F25-G25 -> -14622.576 | I25: ='Tennessee counties'!D49 -> 9075 | J25: =$J$2 -> 23615 | K25: =I25-J25 -> -14540 | L25: ='Tennessee counties'!E49 -> 10486 | M25: =$M$2 -> 26429.859 | N25: =L25-M25 -> -15943.859 | O25: ='Tennessee counties'!F49 -> 11235 | P25: =$P$2 -> 29452.939 | Q25: =O25-P25 -> -18217.939 | R25: ='Tennessee counties'!G49 -> 11655 | S25: =$S$2 -> 33249.677 | T25: =R25-S25 -> -21594.677 | U25: ='Tennessee counties'!H49 -> 9572 | V25: =$V$2 -> 36031.202 | W25: =U25-V25 -> -26459.202
A26: Lauderdale | B26: 1 | C26: ='Tennessee counties'!B27 -> 20392 | D26: =$D$2 -> 20410.263 | E26: =C26-D26 -> -18.262626 | F26: ='Tennessee counties'!C27 -> 20491 | G26: =$G$2 -> 22068.576 | H26: =F26-G26 -> -1577.5758 | I26: ='Tennessee counties'!D50 -> 21494 | J26: =$J$2 -> 23615 | K26: =I26-J26 -> -2121 | L26: ='Tennessee counties'!E50 -> 23406 | M26: =$M$2 -> 26429.859 | N26: =L26-M26 -> -3023.8586 | O26: ='Tennessee counties'!F50 -> 24461 | P26: =$P$2 -> 29452.939 | Q26: =O26-P26 -> -4991.9394 | R26: ='Tennessee counties'!G50 -> 25047 | S26: =$S$2 -> 33249.677 | T26: =R26-S26 -> -8202.6768 | U26: ='Tennessee counties'!H50 -> 21844 | V26: =$V$2 -> 36031.202 | W26: =U26-V26 -> -14187.202
A27: Lawrence | B27: 1 | C27: ='Tennessee counties'!B28 -> 39408 | D27: =$D$2 -> 20410.263 | E27: =C27-D27 -> 18997.737 | F27: ='Tennessee counties'!C28 -> 41630 | G27: =$G$2 -> 22068.576 | H27: =F27-G27 -> 19561.424 | I27: ='Tennessee counties'!D51 -> 23593 | J27: =$J$2 -> 23615 | K27: =I27-J27 -> -22 | L27: ='Tennessee counties'!E51 -> 26776 | M27: =$M$2 -> 26429.859 | N27: =L27-M27 -> 346.14141 | O27: ='Tennessee counties'!F51 -> 28726 | P27: =$P$2 -> 29452.939 | Q27: =O27-P27 -> -726.93939 | R27: ='Tennessee counties'!G51 -> 28818 | S27: =$S$2 -> 33249.677 | T27: =R27-S27 -> -4431.6768 | U27: ='Tennessee counties'!H51 -> 28049 | V27: =$V$2 -> 36031.202 | W27: =U27-V27 -> -7982.202
A28: Lincoln | B28: 1 | C28: ='Tennessee counties'!B29 -> 33035 | D28: =$D$2 -> 20410.263 | E28: =C28-D28 -> 12624.737 | F28: ='Tennessee counties'!C29 -> 32629 | G28: =$G$2 -> 22068.576 | H28: =F28-G28 -> 10560.424 | I28: ='Tennessee counties'!D53 -> 25786 | J28: =$J$2 -> 23615 | K28: =I28-J28 -> 2171 | L28: ='Tennessee counties'!E53 -> 25422 | M28: =$M$2 -> 26429.859 | N28: =L28-M28 -> -1007.8586 | O28: ='Tennessee counties'!F53 -> 27214 | P28: =$P$2 -> 29452.939 | Q28: =O28-P28 -> -2238.9394 | R28: ='Tennessee counties'!G53 -> 25624 | S28: =$S$2 -> 33249.677 | T28: =R28-S28 -> -7625.6768 | U28: ='Tennessee counties'!H53 -> 23829 | V28: =$V$2 -> 36031.202 | W28: =U28-V28 -> -12202.202
A29: Marion | B29: 1 | C29: ='Tennessee counties'!B30 -> 15512 | D29: =$D$2 -> 20410.263 | E29: =C29-D29 -> -4898.2626 | F29: ='Tennessee counties'!C30 -> 13888 | G29: =$G$2 -> 22068.576 | H29: =F29-G29 -> -8180.5758 | I29: ='Tennessee counties'!D57 -> 14922 | J29: =$J$2 -> 23615 | K29: =I29-J29 -> -8693 | L29: ='Tennessee counties'!E57 -> 13872 | M29: =$M$2 -> 26429.859 | N29: =L29-M29 -> -12557.859 | O29: ='Tennessee counties'!F57 -> 14904 | P29: =$P$2 -> 29452.939 | Q29: =O29-P29 -> -14548.939 | R29: ='Tennessee counties'!G57 -> 13599 | S29: =$S$2 -> 33249.677 | T29: =R29-S29 -> -19650.677 | U29: ='Tennessee counties'!H57 -> 12197 | V29: =$V$2 -> 36031.202 | W29: =U29-V29 -> -23834.202
A30: Marshall | B30: 1 | C30: ='Tennessee counties'!B31 -> 30596 | D30: =$D$2 -> 20410.263 | E30: =C30-D30 -> 10185.737 | F30: ='Tennessee counties'!C31 -> 31083 | G30: =$G$2 -> 22068.576 | H30: =F30-G30 -> 9014.4242 | I30: ='Tennessee counties'!D58 -> 43824 | J30: =$J$2 -> 23615 | K30: =I30-J30 -> 20209 | L30: ='Tennessee counties'!E58 -> 51059 | M30: =$M$2 -> 26429.859 | N30: =L30-M30 -> 24629.141 | O30: ='Tennessee counties'!F58 -> 54115 | P30: =$P$2 -> 29452.939 | Q30: =O30-P30 -> 24662.061 | R30: ='Tennessee counties'!G58 -> 60128 | S30: =$S$2 -> 33249.677 | T30: =R30-S30 -> 26878.323 | U30: ='Tennessee counties'!H58 -> 60655 | V30: =$V$2 -> 36031.202 | W30: =U30-V30 -> 24623.798
A31: Maury | B31: 1 | C31: ='Tennessee counties'!B32 -> 7802 | D31: =$D$2 -> 20410.263 | E31: =C31-D31 -> -12608.263 | F31: ='Tennessee counties'!C32 -> 8322 | G31: =$G$2 -> 22068.576 | H31: =F31-G31 -> -13746.576 | I31: ='Tennessee counties'!D59 -> 17402 | J31: =$J$2 -> 23615 | K31: =I31-J31 -> -6213 | L31: ='Tennessee counties'!E59 -> 17549 | M31: =$M$2 -> 26429.859 | N31: =L31-M31 -> -8880.8586 | O31: ='Tennessee counties'!F59 -> 19140 | P31: =$P$2 -> 29452.939 | Q31: =O31-P31 -> -10312.939 | R31: ='Tennessee counties'!G59 -> 20520 | S31: =$S$2 -> 33249.677 | T31: =R31-S31 -> -12729.677 | U31: ='Tennessee counties'!H59 -> 21036 | V31: =$V$2 -> 36031.202 | W31: =U31-V31 -> -14995.202
A32: Monroe | B32: 1 | C32: ='Tennessee counties'!B33 -> 12728 | D32: =$D$2 -> 20410.263 | E32: =C32-D32 -> -7682.2626 | F32: ='Tennessee counties'!C33 -> 13650 | G32: =$G$2 -> 22068.576 | H32: =F32-G32 -> -8418.5758 | I32: ='Tennessee counties'!D63 -> 22060 | J32: =$J$2 -> 23615 | K32: =I32-J32 -> -1555 | L32: ='Tennessee counties'!E63 -> 21377 | M32: =$M$2 -> 26429.859 | N32: =L32-M32 -> -5052.8586 | O32: ='Tennessee counties'!F63 -> 24275 | P32: =$P$2 -> 29452.939 | Q32: =O32-P32 -> -5177.9394 | R32: ='Tennessee counties'!G63 -> 24513 | S32: =$S$2 -> 33249.677 | T32: =R32-S32 -> -8736.6768 | U32: ='Tennessee counties'!H63 -> 23316 | V32: =$V$2 -> 36031.202 | W32: =U32-V32 -> -12715.202
A33: Montgomery | B33: 1 | C33: ='Tennessee counties'!B34 -> 67102 | D33: =$D$2 -> 20410.263 | E33: =C33-D33 -> 46691.737 | F33: ='Tennessee counties'!C34 -> 94477 | G33: =$G$2 -> 22068.576 | H33: =F33-G33 -> 72408.424 | I33: ='Tennessee counties'!D64 -> 32265 | J33: =$J$2 -> 23615 | K33: =I33-J33 -> 8650 | L33: ='Tennessee counties'!E64 -> 30882 | M33: =$M$2 -> 26429.859 | N33: =L33-M33 -> 4452.1414 | O33: ='Tennessee counties'!F64 -> 33346 | P33: =$P$2 -> 29452.939 | Q33: =O33-P33 -> 3893.0606 | R33: ='Tennessee counties'!G64 -> 44186 | S33: =$S$2 -> 33249.677 | T33: =R33-S33 -> 10936.323 | U33: ='Tennessee counties'!H64 -> 55645 | V33: =$V$2 -> 36031.202 | W33: =U33-V33 -> 19613.798
A34: Moore | B34: 1 | C34: ='Tennessee counties'!B35 -> 11147 | D34: =$D$2 -> 20410.263 | E34: =C34-D34 -> -9263.2626 | F34: ='Tennessee counties'!C35 -> 10778 | G34: =$G$2 -> 22068.576 | H34: =F34-G34 -> -11290.576 | I34: ='Tennessee counties'!D65 -> 4491 | J34: =$J$2 -> 23615 | K34: =I34-J34 -> -19124 | L34: ='Tennessee counties'!E65 -> 4037 | M34: =$M$2 -> 26429.859 | N34: =L34-M34 -> -22392.859 | O34: ='Tennessee counties'!F65 -> 4093 | P34: =$P$2 -> 29452.939 | Q34: =O34-P34 -> -25359.939 | R34: ='Tennessee counties'!G65 -> 3948 | S34: =$S$2 -> 33249.677 | T34: =R34-S34 -> -29301.677 | U34: ='Tennessee counties'!H65 -> 3454 | V34: =$V$2 -> 36031.202 | W34: =U34-V34 -> -32577.202
A35: McMinn | B35: 1 | C35: ='Tennessee counties'!B36 -> 22976 | D35: =$D$2 -> 20410.263 | E35: =C35-D35 -> 2565.7374 | F35: ='Tennessee counties'!C36 -> 23011 | G35: =$G$2 -> 22068.576 | H35: =F35-G35 -> 942.42424 | I35: ='Tennessee counties'!D60 -> 17375 | J35: =$J$2 -> 23615 | K35: =I35-J35 -> -6240 | L35: ='Tennessee counties'!E60 -> 15574 | M35: =$M$2 -> 26429.859 | N35: =L35-M35 -> -10855.859 | O35: ='Tennessee counties'!F60 -> 16030 | P35: =$P$2 -> 29452.939 | Q35: =O35-P35 -> -13422.939 | R35: ='Tennessee counties'!G60 -> 17768 | S35: =$S$2 -> 33249.677 | T35: =R35-S35 -> -15481.677 | U35: ='Tennessee counties'!H60 -> 16859 | V35: =$V$2 -> 36031.202 | W35: =U35-V35 -> -19172.202
A36: McNairy | B36: 1 | C36: ='Tennessee counties'!B37 -> 19246 | D36: =$D$2 -> 20410.263 | E36: =C36-D36 -> -1164.2626 | F36: ='Tennessee counties'!C37 -> 17521 | G36: =$G$2 -> 22068.576 | H36: =F36-G36 -> -4547.5758 | I36: ='Tennessee counties'!D61 -> 35403 | J36: =$J$2 -> 23615 | K36: =I36-J36 -> 11788 | L36: ='Tennessee counties'!E61 -> 34016 | M36: =$M$2 -> 26429.859 | N36: =L36-M36 -> 7586.1414 | O36: ='Tennessee counties'!F61 -> 40357 | P36: =$P$2 -> 29452.939 | Q36: =O36-P36 -> 10904.061 | R36: ='Tennessee counties'!G61 -> 40368 | S36: =$S$2 -> 33249.677 | T36: =R36-S36 -> 7118.3232 | U36: ='Tennessee counties'!H61 -> 41699 | V36: =$V$2 -> 36031.202 | W36: =U36-V36 -> 5667.798
A37: Obion | B37: 1 | C37: ='Tennessee counties'!B38 -> 24267 | D37: =$D$2 -> 20410.263 | E37: =C37-D37 -> 3856.7374 | F37: ='Tennessee counties'!C38 -> 23587 | G37: =$G$2 -> 22068.576 | H37: =F37-G37 -> 1518.4242 | I37: ='Tennessee counties'!D67 -> 28393 | J37: =$J$2 -> 23615 | K37: =I37-J37 -> 4778 | L37: ='Tennessee counties'!E67 -> 29086 | M37: =$M$2 -> 26429.859 | N37: =L37-M37 -> 2656.1414 | O37: ='Tennessee counties'!F67 -> 30978 | P37: =$P$2 -> 29452.939 | Q37: =O37-P37 -> 1525.0606 | R37: ='Tennessee counties'!G67 -> 29056 | S37: =$S$2 -> 33249.677 | T37: =R37-S37 -> -4193.6768 | U37: ='Tennessee counties'!H67 -> 26957 | V37: =$V$2 -> 36031.202 | W37: =U37-V37 -> -9074.202
A38: Overton | B38: 1 | C38: ='Tennessee counties'!B39 -> 25189 | D38: =$D$2 -> 20410.263 | E38: =C38-D38 -> 4778.7374 | F38: ='Tennessee counties'!C39 -> 25910 | G38: =$G$2 -> 22068.576 | H38: =F38-G38 -> 3841.4242 | I38: ='Tennessee counties'!D68 -> 17617 | J38: =$J$2 -> 23615 | K38: =I38-J38 -> -5998 | L38: ='Tennessee counties'!E68 -> 18079 | M38: =$M$2 -> 26429.859 | N38: =L38-M38 -> -8350.8586 | O38: ='Tennessee counties'!F68 -> 18883 | P38: =$P$2 -> 29452.939 | Q38: =O38-P38 -> -10569.939 | R38: ='Tennessee counties'!G68 -> 17566 | S38: =$S$2 -> 33249.677 | T38: =R38-S38 -> -15683.677 | U38: ='Tennessee counties'!H68 -> 14661 | V38: =$V$2 -> 36031.202 | W38: =U38-V38 -> -21370.202
A39: Putnam | B39: 1 | C39: ='Tennessee counties'!B40 -> 18117 | D39: =$D$2 -> 20410.263 | E39: =C39-D39 -> -2293.2626 | F39: ='Tennessee counties'!C40 -> 17030 | G39: =$G$2 -> 22068.576 | H39: =F39-G39 -> -5038.5758 | I39: ='Tennessee counties'!D72 -> 22231 | J39: =$J$2 -> 23615 | K39: =I39-J39 -> -1384 | L39: ='Tennessee counties'!E72 -> 23759 | M39: =$M$2 -> 26429.859 | N39: =L39-M39 -> -2670.8586 | O39: ='Tennessee counties'!F72 -> 26250 | P39: =$P$2 -> 29452.939 | Q39: =O39-P39 -> -3202.9394 | R39: ='Tennessee counties'!G72 -> 29869 | S39: =$S$2 -> 33249.677 | T39: =R39-S39 -> -3380.6768 | U39: ='Tennessee counties'!H72 -> 29236 | V39: =$V$2 -> 36031.202 | W39: =U39-V39 -> -6795.202
A40: Roane | B40: 1 | C40: ='Tennessee counties'!B41 -> 24208 | D40: =$D$2 -> 20410.263 | E40: =C40-D40 -> 3797.7374 | F40: ='Tennessee counties'!C41 -> 25434 | G40: =$G$2 -> 22068.576 | H40: =F40-G40 -> 3365.4242 | I40: ='Tennessee counties'!D74 -> 24624 | J40: =$J$2 -> 23615 | K40: =I40-J40 -> 1009 | L40: ='Tennessee counties'!E74 -> 24477 | M40: =$M$2 -> 26429.859 | N40: =L40-M40 -> -1952.8586 | O40: ='Tennessee counties'!F74 -> 27795 | P40: =$P$2 -> 29452.939 | Q40: =O40-P40 -> -1657.9394 | R40: ='Tennessee counties'!G74 -> 31665 | S40: =$S$2 -> 33249.677 | T40: =R40-S40 -> -1584.6768 | U40: ='Tennessee counties'!H74 -> 39133 | V40: =$V$2 -> 36031.202 | W40: =U40-V40 -> 3101.798
...

Sheet Senate districts
A1: seat | B1: counties | C1: 1900 population | D1: ideal population | E1: deviation | F1: 1910 | G1: ideal population | H1: deviation | I1: 1920 | J1: ideal population | K1: deviation | L1: 1930 | M1: ideal population | N1: deviation | O1: 1940 | P1: ideal population | Q1: deviation | R1: 1950 | S1: ideal population | T1: deviation | U1: 1960 | V1: ideal population | W1: deviation
A2: 1 | B2: Johnson, Carter, Unicoi, Greene, & Washington | C2: ='Tennessee counties'!B47+'Tennessee counties'!B11+'Tennessee counties'!B31+'Tennessee counties'!B87+'Tennessee counties'!B91 -> 86328 | D2: =SUM('Tennessee counties'!B2:B96)/33 -> 61230.788 | E2: =C2-D2 -> 25097.212 | F2: ='Tennessee counties'!C47+'Tennessee counties'!C11+'Tennessee counties'!C31+'Tennessee counties'!C87+'Tennessee counties'!C91 -> 100281 | G2: =SUM('Tennessee counties'!C2:C96)/33 -> 66205.727 | H2: =F2-G2 -> 34075.273 | I2: ='Tennessee counties'!D47+'Tennessee counties'!D11+'Tennessee counties'!D31+'Tennessee counties'!D87+'Tennessee counties'!D91 -> 110714 | J2: =SUM('Tennessee counties'!D2:D96)/33 -> 70845 | K2: =I2-J2 -> 39869 | L2: ='Tennessee counties'!E47+'Tennessee counties'!E11+'Tennessee counties'!E31+'Tennessee counties'!E87+'Tennessee counties'!E91 -> 135034 | M2: =SUM('Tennessee counties'!E2:E96)/33 -> 79289.576 | N2: =L2-M2 -> 55744.424 | O2: ='Tennessee counties'!F47+'Tennessee counties'!F11+'Tennessee counties'!F31+'Tennessee counties'!F87+'Tennessee counties'!F91 -> 153289 | P2: =SUM('Tennessee counties'!F2:F96)/33 -> 88358.818 | Q2: =O2-P2 -> 64930.182 | R2: ='Tennessee counties'!G47+'Tennessee counties'!G11+'Tennessee counties'!G31+'Tennessee counties'!G87+'Tennessee counties'!G91 -> 171615 | S2: =SUM('Tennessee counties'!G2:G96)/33 -> 99749.03 | T2: =R2-S2 -> 71865.97 | U2: ='Tennessee counties'!H47+'Tennessee counties'!H11+'Tennessee counties'!H31+'Tennessee counties'!H87+'Tennessee counties'!H91 -> 174420 | V2: =SUM('Tennessee counties'!H2:H96)/33 -> 108093.61 | W2: =U2-V2 -> 66326.394
A3: 2 | B3: Sullivan & Hawkins | C3: ='Tennessee counties'!B83+'Tennessee counties'!B38 -> 49202 | D3: =$D$2 -> 61230.788 | E3: =C3-D3 -> -12028.788 | F3: ='Tennessee counties'!C83+'Tennessee counties'!C38 -> 51707 | G3: =$G$2 -> 66205.727 | H3: =F3-G3 -> -14498.727 | I3: ='Tennessee counties'!D83+'Tennessee counties'!D38 -> 59177 | J3: =$J$2 -> 70845 | K3: =I3-J3 -> -11668 | L3: ='Tennessee counties'!E83+'Tennessee counties'!E38 -> 75204 | M3: =$M$2 -> 79289.576 | N3: =L3-M3 -> -4085.5758 | O3: ='Tennessee counties'!F83+'Tennessee counties'!F38 -> 97608 | P3: =$P$2 -> 88358.818 | Q3: =O3-P3 -> 9249.1818 | R3: ='Tennessee counties'!G83+'Tennessee counties'!G38 -> 125557 | S3: =$S$2 -> 99749.03 | T3: =R3-S3 -> 25807.97 | U3: ='Tennessee counties'!H83+'Tennessee counties'!H38 -> 144607 | V3: =$V$2 -> 108093.61 | W3: =U3-V3 -> 36513.394
A4: 3 | B4: Hancock, Morgan, Grainger, Claiborne, Union, Campbell, & Scott | C4: ='Tennessee counties'!B35+'Tennessee counties'!B66+'Tennessee counties'!B30+'Tennessee counties'!B14+'Tennessee counties'!B88+'Tennessee counties'!B8+'Tennessee counties'!B77 -> 98230 | D4: =$D$2 -> 61230.788 | E4: =C4-D4 -> 36999.212 | F4: ='Tennessee counties'!C35+'Tennessee counties'!C66+'Tennessee counties'!C30+'Tennessee counties'!C14+'Tennessee counties'!C88+'Tennessee counties'!C8+'Tennessee counties'!C77 -> 111376 | G4: =$G$2 -> 66205.727 | H4: =F4-G4 -> 45170.273 | I4: ='Tennessee counties'!D35+'Tennessee counties'!D66+'Tennessee counties'!D30+'Tennessee counties'!D14+'Tennessee counties'!D88+'Tennessee counties'!D8+'Tennessee counties'!D77 -> 113685 | J4: =$J$2 -> 70845 | K4: =I4-J4 -> 42840 | L4: ='Tennessee counties'!E35+'Tennessee counties'!E66+'Tennessee counties'!E30+'Tennessee counties'!E14+'Tennessee counties'!E88+'Tennessee counties'!E8+'Tennessee counties'!E77 -> 112604 | M4: =$M$2 -> 79289.576 | N4: =L4-M4 -> 33314.424 | O4: ='Tennessee counties'!F35+'Tennessee counties'!F66+'Tennessee counties'!F30+'Tennessee counties'!F14+'Tennessee counties'!F88+'Tennessee counties'!F8+'Tennessee counties'!F77 -> 121613 | P4: =$P$2 -> 88358.818 | Q4: =O4-P4 -> 33254.182 | R4: ='Tennessee counties'!G35+'Tennessee counties'!G66+'Tennessee counties'!G30+'Tennessee counties'!G14+'Tennessee counties'!G88+'Tennessee counties'!G8+'Tennessee counties'!G77 -> 123118 | S4: =$S$2 -> 99749.03 | T4: =R4-S4 -> 23368.97 | U4: ='Tennessee counties'!H35+'Tennessee counties'!H66+'Tennessee counties'!H30+'Tennessee counties'!H14+'Tennessee counties'!H88+'Tennessee counties'!H8+'Tennessee counties'!H77 -> 105481 | V4: =$V$2 -> 108093.61 | W4: =U4-V4 -> -2612.6061
A5: 4 | B5: Cocke, Hamblen, Jefferson, Sevier, & Blount | C5: ='Tennessee counties'!B16+'Tennessee counties'!B34+'Tennessee counties'!B46+'Tennessee counties'!B6+'Tennessee counties'!B79 -> 146072 | D5: =$D$2 -> 61230.788 | E5: =C5-D5 -> 84841.212 | F5: ='Tennessee counties'!C16+'Tennessee counties'!C34+'Tennessee counties'!C46+'Tennessee counties'!C6+'Tennessee counties'!C79 -> 174736 | G5: =$G$2 -> 66205.727 | H5: =F5-G5 -> 108530.27 | I5: ='Tennessee counties'!D16+'Tennessee counties'!D34+'Tennessee counties'!D46+'Tennessee counties'!D6+'Tennessee counties'!D79 -> 205597 | J5: =$J$2 -> 70845 | K5: =I5-J5 -> 134752 | L5: ='Tennessee counties'!E16+'Tennessee counties'!E34+'Tennessee counties'!E46+'Tennessee counties'!E6+'Tennessee counties'!E79 -> 253655 | M5: =$M$2 -> 79289.576 | N5: =L5-M5 -> 174365.42 | O5: ='Tennessee counties'!F16+'Tennessee counties'!F34+'Tennessee counties'!F46+'Tennessee counties'!F6+'Tennessee counties'!F79 -> 287589 | P5: =$P$2 -> 88358.818 | Q5: =O5-P5 -> 199230.18 | R5: ='Tennessee counties'!G16+'Tennessee counties'!G34+'Tennessee counties'!G46+'Tennessee counties'!G6+'Tennessee counties'!G79 -> 328979 | S5: =$S$2 -> 99749.03 | T5: =R5-S5 -> 229229.97 | U5: ='Tennessee counties'!H16+'Tennessee counties'!H34+'Tennessee counties'!H46+'Tennessee counties'!H6+'Tennessee counties'!H79 -> 364564 | V5: =$V$2 -> 108093.61 | W5: =U5-V5 -> 256470.39
A6: 5 | B6: Knox | C6: ='Tennessee counties'!B48 -> 74302 | D6: =$D$2 -> 61230.788 | E6: =C6-D6 -> 13071.212 | F6: ='Tennessee counties'!C48 -> 94187 | G6: =$G$2 -> 66205.727 | H6: =F6-G6 -> 27981.273 | I6: ='Tennessee counties'!D48 -> 112926 | J6: =$J$2 -> 70845 | K6: =I6-J6 -> 42081 | L6: ='Tennessee counties'!E48 -> 155902 | M6: =$M$2 -> 79289.576 | N6: =L6-M6 -> 76612.424 | O6: ='Tennessee counties'!F48 -> 178468 | P6: =$P$2 -> 88358.818 | Q6: =O6-P6 -> 90109.182 | R6: ='Tennessee counties'!G48 -> 223007 | S6: =$S$2 -> 99749.03 | T6: =R6-S6 -> 123257.97 | U6: ='Tennessee counties'!H48 -> 250523 | V6: =$V$2 -> 108093.61 | W6: =U6-V6 -> 142429.39
A7: 6 | B7: Knox, Loudon, Anderson, & Roane | C7: ='Tennessee counties'!B48+'Tennessee counties'!B54+'Tennessee counties'!B2+'Tennessee counties'!B74 -> 125512 | D7: =$D$2 -> 61230.788 | E7: =C7-D7 -> 64281.212 | F7: ='Tennessee counties'!C48+'Tennessee counties'!C54+'Tennessee counties'!C2+'Tennessee counties'!C74 -> 148376 | G7: =$G$2 -> 66205.727 | H7: =F7-G7 -> 82170.273 | I7: ='Tennessee counties'!D48+'Tennessee counties'!D54+'Tennessee counties'!D2+'Tennessee counties'!D74 -> 172123 | J7: =$J$2 -> 70845 | K7: =I7-J7 -> 101278 | L7: ='Tennessee counties'!E48+'Tennessee counties'!E54+'Tennessee counties'!E2+'Tennessee counties'!E74 -> 217906 | M7: =$M$2 -> 79289.576 | N7: =L7-M7 -> 138616.42 | O7: ='Tennessee counties'!F48+'Tennessee counties'!F54+'Tennessee counties'!F2+'Tennessee counties'!F74 -> 252605 | P7: =$P$2 -> 88358.818 | Q7: =O7-P7 -> 164246.18 | R7: ='Tennessee counties'!G48+'Tennessee counties'!G54+'Tennessee counties'!G2+'Tennessee counties'!G74 -> 337261 | S7: =$S$2 -> 99749.03 | T7: =R7-S7 -> 237511.97 | U7: ='Tennessee counties'!H48+'Tennessee counties'!H54+'Tennessee counties'!H2+'Tennessee counties'!H74 -> 373445 | V7: =$V$2 -> 108093.61 | W7: =U7-V7 -> 265351.39
A8: 7 | B8: McMinn, Bradley, Monroe, & Polk | C8: ='Tennessee counties'!B60+'Tennessee counties'!B7+'Tennessee counties'!B63+'Tennessee counties'!B71 -> 64464 | D8: =$D$2 -> 61230.788 | E8: =C8-D8 -> 3233.2121 | F8: ='Tennessee counties'!C60+'Tennessee counties'!C7+'Tennessee counties'!C63+'Tennessee counties'!C71 -> 68040 | G8: =$G$2 -> 66205.727 | H8: =F8-G8 -> 1834.2727 | I8: ='Tennessee counties'!D60+'Tennessee counties'!D7+'Tennessee counties'!D63+'Tennessee counties'!D71 -> 72330 | J8: =$J$2 -> 70845 | K8: =I8-J8 -> 1485 | L8: ='Tennessee counties'!E60+'Tennessee counties'!E7+'Tennessee counties'!E63+'Tennessee counties'!E71 -> 75507 | M8: =$M$2 -> 79289.576 | N8: =L8-M8 -> -3782.5758 | O8: ='Tennessee counties'!F60+'Tennessee counties'!F7+'Tennessee counties'!F63+'Tennessee counties'!F71 -> 84276 | P8: =$P$2 -> 88358.818 | Q8: =O8-P8 -> -4082.8182 | R8: ='Tennessee counties'!G60+'Tennessee counties'!G7+'Tennessee counties'!G63+'Tennessee counties'!G71 -> 88693 | S8: =$S$2 -> 99749.03 | T8: =R8-S8 -> -11056.03 | U8: ='Tennessee counties'!H60+'Tennessee counties'!H7+'Tennessee counties'!H63+'Tennessee counties'!H71 -> 90659 | V8: =$V$2 -> 108093.61 | W8: =U8-V8 -> -17434.606
A9: 8 | B9: Hamilton | C9: ='Tennessee counties'!B34 -> 67102 | D9: =$D$2 -> 61230.788 | E9: =C9-D9 -> 5871.2121 | F9: ='Tennessee counties'!C34 -> 94477 | G9: =$G$2 -> 66205.727 | H9: =F9-G9 -> 28271.273 | I9: ='Tennessee counties'!D34 -> 115954 | J9: =$J$2 -> 70845 | K9: =I9-J9 -> 45109 | L9: ='Tennessee counties'!E34 -> 159497 | M9: =$M$2 -> 79289.576 | N9: =L9-M9 -> 80207.424 | O9: ='Tennessee counties'!F34 -> 180478 | P9: =$P$2 -> 88358.818 | Q9: =O9-P9 -> 92119.182 | R9: ='Tennessee counties'!G34 -> 208255 | S9: =$S$2 -> 99749.03 | T9: =R9-S9 -> 108505.97 | U9: ='Tennessee counties'!H34 -> 237905 | V9: =$V$2 -> 108093.61 | W9: =U9-V9 -> 129811.39
A10: 9 | B10: Rhea, Meigs, Bledsoe, Sequatchie, Van Buren, White, & Cumberland | C10: ='Tennessee counties'!B73+'Tennessee counties'!B62+'Tennessee counties'!B5+'Tennessee counties'!B78+'Tennessee counties'!B89+'Tennessee counties'!B94+'Tennessee counties'!B19 -> 57355 | D10: =$D$2 -> 61230.788 | E10: =C10-D10 -> -3875.7879 | F10: ='Tennessee counties'!C73+'Tennessee counties'!C62+'Tennessee counties'!C5+'Tennessee counties'!C78+'Tennessee counties'!C89+'Tennessee counties'!C94+'Tennessee counties'!C19 -> 59603 | G10: =$G$2 -> 66205.727 | H10: =F10-G10 -> -6602.7273 | I10: ='Tennessee counties'!D73+'Tennessee counties'!D62+'Tennessee counties'!D5+'Tennessee counties'!D78+'Tennessee counties'!D89+'Tennessee counties'!D94+'Tennessee counties'!D19 -> 59158 | J10: =$J$2 -> 70845 | K10: =I10-J10 -> -11687 | L10: ='Tennessee counties'!E73+'Tennessee counties'!E62+'Tennessee counties'!E5+'Tennessee counties'!E78+'Tennessee counties'!E89+'Tennessee counties'!E94+'Tennessee counties'!E19 -> 61672 | M10: =$M$2 -> 79289.576 | N10: =L10-M10 -> -17617.576 | O10: ='Tennessee counties'!F73+'Tennessee counties'!F62+'Tennessee counties'!F5+'Tennessee counties'!F78+'Tennessee counties'!F89+'Tennessee counties'!F94+'Tennessee counties'!F19 -> 71807 | P10: =$P$2 -> 88358.818 | Q10: =O10-P10 -> -16551.818 | R10: ='Tennessee counties'!G73+'Tennessee counties'!G62+'Tennessee counties'!G5+'Tennessee counties'!G78+'Tennessee counties'!G89+'Tennessee counties'!G94+'Tennessee counties'!G19 -> 75433 | S10: =$S$2 -> 99749.03 | T10: =R10-S10 -> -24316.03 | U10: ='Tennessee counties'!H73+'Tennessee counties'!H62+'Tennessee counties'!H5+'Tennessee counties'!H78+'Tennessee counties'!H89+'Tennessee counties'!H94+'Tennessee counties'!H19 -> 73132 | V10: =$V$2 -> 108093.61 | W10: =U10-V10 -> -34961.606
A11: 10 | B11: Fentress, Pickett, Clay, Overton, Putnam, & Jackson | C11: ='Tennessee counties'!B26+'Tennessee counties'!B70+'Tennessee counties'!B15+'Tennessee counties'!B68+'Tennessee counties'!B72+'Tennessee counties'!B45 -> 65175 | D11: =$D$2 -> 61230.788 | E11: =C11-D11 -> 3944.2121 | F11: ='Tennessee counties'!C26+'Tennessee counties'!C70+'Tennessee counties'!C15+'Tennessee counties'!C68+'Tennessee counties'!C72+'Tennessee counties'!C45 -> 72455 | G11: =$G$2 -> 66205.727 | H11: =F11-G11 -> 6249.2727 | I11: ='Tennessee counties'!D26+'Tennessee counties'!D70+'Tennessee counties'!D15+'Tennessee counties'!D68+'Tennessee counties'!D72+'Tennessee counties'!D45 -> 79636 | J11: =$J$2 -> 70845 | K11: =I11-J11 -> 8791 | L11: ='Tennessee counties'!E26+'Tennessee counties'!E70+'Tennessee counties'!E15+'Tennessee counties'!E68+'Tennessee counties'!E72+'Tennessee counties'!E45 -> 81655 | M11: =$M$2 -> 79289.576 | N11: =L11-M11 -> 2365.4242 | O11: ='Tennessee counties'!F26+'Tennessee counties'!F70+'Tennessee counties'!F15+'Tennessee counties'!F68+'Tennessee counties'!F72+'Tennessee counties'!F45 -> 91594 | P11: =$P$2 -> 88358.818 | Q11: =O11-P11 -> 3235.1818 | R11: ='Tennessee counties'!G26+'Tennessee counties'!G70+'Tennessee counties'!G15+'Tennessee counties'!G68+'Tennessee counties'!G72+'Tennessee counties'!G45 -> 88494 | S11: =$S$2 -> 99749.03 | T11: =R11-S11 -> -11255.03 | U11: ='Tennessee counties'!H26+'Tennessee counties'!H70+'Tennessee counties'!H15+'Tennessee counties'!H68+'Tennessee counties'!H72+'Tennessee counties'!H45 -> 78138 | V11: =$V$2 -> 108093.61 | W11: =U11-V11 -> -29955.606
A12: 11 | B12: Marion, Franklin, Grundy, & Warren | C12: ='Tennessee counties'!B57+'Tennessee counties'!B27+'Tennessee counties'!B32+'Tennessee counties'!B90 -> 57485 | D12: =$D$2 -> 61230.788 | E12: =C12-D12 -> -3745.7879 | F12: ='Tennessee counties'!C57+'Tennessee counties'!C27+'Tennessee counties'!C32+'Tennessee counties'!C90 -> 59906 | G12: =$G$2 -> 66205.727 | H12: =F12-G12 -> -6299.7273 | I12: ='Tennessee counties'!D57+'Tennessee counties'!D27+'Tennessee counties'!D32+'Tennessee counties'!D90 -> 62622 | J12: =$J$2 -> 70845 | K12: =I12-J12 -> -8223 | L12: ='Tennessee counties'!E57+'Tennessee counties'!E27+'Tennessee counties'!E32+'Tennessee counties'!E90 -> 65594 | M12: =$M$2 -> 79289.576 | N12: =L12-M12 -> -13695.576 | O12: ='Tennessee counties'!F57+'Tennessee counties'!F27+'Tennessee counties'!F32+'Tennessee counties'!F90 -> 70112 | P12: =$P$2 -> 88358.818 | Q12: =O12-P12 -> -18246.818 | R12: ='Tennessee counties'!G57+'Tennessee counties'!G27+'Tennessee counties'!G32+'Tennessee counties'!G90 -> 73859 | S12: =$S$2 -> 99749.03 | T12: =R12-S12 -> -25890.03 | U12: ='Tennessee counties'!H57+'Tennessee counties'!H27+'Tennessee counties'!H32+'Tennessee counties'!H90 -> 72339 | V12: =$V$2 -> 108093.61 | W12: =U12-V12 -> -35754.606
A13: 12 | B13: Rutherford, Cannon, & DeKalb | C13: ='Tennessee counties'!B76+'Tennessee counties'!B9+'Tennessee counties'!B22 -> 62124 | D13: =$D$2 -> 61230.788 | E13: =C13-D13 -> 893.21212 | F13: ='Tennessee counties'!C76+'Tennessee counties'!C9+'Tennessee counties'!C22 -> 59458 | G13: =$G$2 -> 66205.727 | H13: =F13-G13 -> -6747.7273 | I13: ='Tennessee counties'!D76+'Tennessee counties'!D9+'Tennessee counties'!D22 -> 58670 | J13: =$J$2 -> 70845 | K13: =I13-J13 -> -12175 | L13: ='Tennessee counties'!E76+'Tennessee counties'!E9+'Tennessee counties'!E22 -> 55434 | M13: =$M$2 -> 79289.576 | N13: =L13-M13 -> -23855.576 | O13: ='Tennessee counties'!F76+'Tennessee counties'!F9+'Tennessee counties'!F22 -> 58072 | P13: =$P$2 -> 88358.818 | Q13: =O13-P13 -> -30286.818 | R13: ='Tennessee counties'!G76+'Tennessee counties'!G9+'Tennessee counties'!G22 -> 61550 | S13: =$S$2 -> 99749.03 | T13: =R13-S13 -> -38199.03 | U13: ='Tennessee counties'!H76+'Tennessee counties'!H9+'Tennessee counties'!H22 -> 71679 | V13: =$V$2 -> 108093.61 | W13: =U13-V13 -> -36414.606
A14: 13 | B14: Wilson & Smith | C14: ='Tennessee counties'!B96+'Tennessee counties'!B81 -> 46104 | D14: =$D$2 -> 61230.788 | E14: =C14-D14 -> -15126.788 | F14: ='Tennessee counties'!C96+'Tennessee counties'!C81 -> 43942 | G14: =$G$2 -> 66205.727 | H14: =F14-G14 -> -22263.727 | I14: ='Tennessee counties'!D96+'Tennessee counties'!D81 -> 43375 | J14: =$J$2 -> 70845 | K14: =I14-J14 -> -27470 | L14: ='Tennessee counties'!E96+'Tennessee counties'!E81 -> 39402 | M14: =$M$2 -> 79289.576 | N14: =L14-M14 -> -39887.576 | O14: ='Tennessee counties'!F96+'Tennessee counties'!F81 -> 41415 | P14: =$P$2 -> 88358.818 | Q14: =O14-P14 -> -46943.818 | R14: ='Tennessee counties'!G96+'Tennessee counties'!G81 -> 40416 | S14: =$S$2 -> 99749.03 | T14: =R14-S14 -> -59333.03 | U14: ='Tennessee counties'!H96+'Tennessee counties'!H81 -> 39727 | V14: =$V$2 -> 108093.61 | W14: =U14-V14 -> -68366.606
A15: 14 | B15: Sumner, Trousdale, & Macon | C15: ='Tennessee counties'!B84+'Tennessee counties'!B86+'Tennessee counties'!B55 -> 51239 | D15: =$D$2 -> 61230.788 | E15: =C15-D15 -> -9991.7879 | F15: ='Tennessee counties'!C84+'Tennessee counties'!C86+'Tennessee counties'!C55 -> 52541 | G15: =$G$2 -> 66205.727 | H15: =F15-G15 -> -13664.727 | I15: ='Tennessee counties'!D84+'Tennessee counties'!D86+'Tennessee counties'!D55 -> 58837 | J15: =$J$2 -> 70845 | K15: =I15-J15 -> -12008 | L15: ='Tennessee counties'!E84+'Tennessee counties'!E86+'Tennessee counties'!E55 -> 63270 | M15: =$M$2 -> 79289.576 | N15: =L15-M15 -> -16019.576 | O15: ='Tennessee counties'!F84+'Tennessee counties'!F86+'Tennessee counties'!F55 -> 69613 | P15: =$P$2 -> 88358.818 | Q15: =O15-P15 -> -18745.818 | R15: ='Tennessee counties'!G84+'Tennessee counties'!G86+'Tennessee counties'!G55 -> 71077 | S15: =$S$2 -> 99749.03 | T15: =R15-S15 -> -28672.03 | U15: ='Tennessee counties'!H84+'Tennessee counties'!H86+'Tennessee counties'!H55 -> 74793 | V15: =$V$2 -> 108093.61 | W15: =U15-V15 -> -33300.606
A16: 15 | B16: Montgomery & Robertson | C16: ='Tennessee counties'!B64+'Tennessee counties'!B75 -> 61046 | D16: =$D$2 -> 61230.788 | E16: =C16-D16 -> -184.78788 | F16: ='Tennessee counties'!C64+'Tennessee counties'!C75 -> 59138 | G16: =$G$2 -> 66205.727 | H16: =F16-G16 -> -7067.7273 | I16: ='Tennessee counties'!D64+'Tennessee counties'!D75 -> 57886 | J16: =$J$2 -> 70845 | K16: =I16-J16 -> -12959 | L16: ='Tennessee counties'!E64+'Tennessee counties'!E75 -> 59073 | M16: =$M$2 -> 79289.576 | N16: =L16-M16 -> -20216.576 | O16: ='Tennessee counties'!F64+'Tennessee counties'!F75 -> 62392 | P16: =$P$2 -> 88358.818 | Q16: =O16-P16 -> -25966.818 | R16: ='Tennessee counties'!G64+'Tennessee counties'!G75 -> 71210 | S16: =$S$2 -> 99749.03 | T16: =R16-S16 -> -28539.03 | U16: ='Tennessee counties'!H64+'Tennessee counties'!H75 -> 82980 | V16: =$V$2 -> 108093.61 | W16: =U16-V16 -> -25113.606
A17: 16 | B17: Davidson | C17: ='Tennessee counties'!B20 -> 122815 | D17: =$D$2 -> 61230.788 | E17: =C17-D17 -> 61584.212 | F17: ='Tennessee counties'!C20 -> 149478 | G17: =$G$2 -> 66205.727 | H17: =F17-G17 -> 83272.273 | I17: ='Tennessee counties'!D20 -> 167815 | J17: =$J$2 -> 70845 | K17: =I17-J17 -> 96970 | L17: ='Tennessee counties'!E20 -> 222854 | M17: =$M$2 -> 79289.576 | N17: =L17-M17 -> 143564.42 | O17: ='Tennessee counties'!F20 -> 257267 | P17: =$P$2 -> 88358.818 | Q17: =O17-P17 -> 168908.18 | R17: ='Tennessee counties'!G20 -> 321758 | S17: =$S$2 -> 99749.03 | T17: =R17-S17 -> 222008.97 | U17: ='Tennessee counties'!H20 -> 399743 | V17: =$V$2 -> 108093.61 | W17: =U17-V17 -> 291649.39
A18: 17 | B18: Davidson | C18: ='Tennessee counties'!B20 -> 122815 | D18: =$D$2 -> 61230.788 | E18: =C18-D18 -> 61584.212 | F18: ='Tennessee counties'!C20 -> 149478 | G18: =$G$2 -> 66205.727 | H18: =F18-G18 -> 83272.273 | I18: ='Tennessee counties'!D20 -> 167815 | J18: =$J$2 -> 70845 | K18: =I18-J18 -> 96970 | L18: ='Tennessee counties'!E20 -> 222854 | M18: =$M$2 -> 79289.576 | N18: =L18-M18 -> 143564.42 | O18: ='Tennessee counties'!F20 -> 257267 | P18: =$P$2 -> 88358.818 | Q18: =O18-P18 -> 168908.18 | R18: ='Tennessee counties'!G20 -> 321758 | S18: =$S$2 -> 99749.03 | T18: =R18-S18 -> 222008.97 | U18: ='Tennessee counties'!H20 -> 399743 | V18: =$V$2 -> 108093.61 | W18: =U18-V18 -> 291649.39
A19: 18 | B19: Bedford, Coffee, & Moore | C19: ='Tennessee counties'!B3+'Tennessee counties'!B17+'Tennessee counties'!B65 -> 45125 | D19: =$D$2 -> 61230.788 | E19: =C19-D19 -> -16105.788 | F19: ='Tennessee counties'!C3+'Tennessee counties'!C17+'Tennessee counties'!C65 -> 43092 | G19: =$G$2 -> 66205.727 | H19: =F19-G19 -> -23113.727 | I19: ='Tennessee counties'!D3+'Tennessee counties'!D17+'Tennessee counties'!D65 -> 43572 | J19: =$J$2 -> 70845 | K19: =I19-J19 -> -27273 | L19: ='Tennessee counties'!E3+'Tennessee counties'!E17+'Tennessee counties'!E65 -> 41915 | M19: =$M$2 -> 79289.576 | N19: =L19-M19 -> -37374.576 | O19: ='Tennessee counties'!F3+'Tennessee counties'!F17+'Tennessee counties'!F65 -> 46203 | P19: =$P$2 -> 88358.818 | Q19: =O19-P19 -> -42155.818 | R19: ='Tennessee counties'!G3+'Tennessee counties'!G17+'Tennessee counties'!G65 -> 50624 | S19: =$S$2 -> 99749.03 | T19: =R19-S19 -> -49125.03 | U19: ='Tennessee counties'!H3+'Tennessee counties'!H17+'Tennessee counties'!H65 -> 55207 | V19: =$V$2 -> 108093.61 | W19: =U19-V19 -> -52886.606
A20: 19 | B20: Lincoln & Marshall | C20: ='Tennessee counties'!B53+'Tennessee counties'!B58 -> 62637 | D20: =$D$2 -> 61230.788 | E20: =C20-D20 -> 1406.2121 | F20: ='Tennessee counties'!C53+'Tennessee counties'!C58 -> 65265 | G20: =$G$2 -> 66205.727 | H20: =F20-G20 -> -940.72727 | I20: ='Tennessee counties'!D53+'Tennessee counties'!D58 -> 69610 | J20: =$J$2 -> 70845 | K20: =I20-J20 -> -1235 | L20: ='Tennessee counties'!E53+'Tennessee counties'!E58 -> 76481 | M20: =$M$2 -> 79289.576 | N20: =L20-M20 -> -2808.5758 | O20: ='Tennessee counties'!F53+'Tennessee counties'!F58 -> 81329 | P20: =$P$2 -> 88358.818 | Q20: =O20-P20 -> -7029.8182 | R20: ='Tennessee counties'!G53+'Tennessee counties'!G58 -> 85752 | S20: =$S$2 -> 99749.03 | T20: =R20-S20 -> -13997.03 | U20: ='Tennessee counties'!H53+'Tennessee counties'!H58 -> 84484 | V20: =$V$2 -> 108093.61 | W20: =U20-V20 -> -23609.606
A21: 20 | B21: Maury, Perry, & Lewis | C21: ='Tennessee counties'!B59+'Tennessee counties'!B69+'Tennessee counties'!B52 -> 30536 | D21: =$D$2 -> 61230.788 | E21: =C21-D21 -> -30694.788 | F21: ='Tennessee counties'!C59+'Tennessee counties'!C69+'Tennessee counties'!C52 -> 33668 | G21: =$G$2 -> 66205.727 | H21: =F21-G21 -> -32537.727 | I21: ='Tennessee counties'!D59+'Tennessee counties'!D69+'Tennessee counties'!D52 -> 30874 | J21: =$J$2 -> 70845 | K21: =I21-J21 -> -39971 | L21: ='Tennessee counties'!E59+'Tennessee counties'!E69+'Tennessee counties'!E52 -> 29954 | M21: =$M$2 -> 79289.576 | N21: =L21-M21 -> -49335.576 | O21: ='Tennessee counties'!F59+'Tennessee counties'!F69+'Tennessee counties'!F52 -> 32524 | P21: =$P$2 -> 88358.818 | Q21: =O21-P21 -> -55834.818 | R21: ='Tennessee counties'!G59+'Tennessee counties'!G69+'Tennessee counties'!G52 -> 33060 | S21: =$S$2 -> 99749.03 | T21: =R21-S21 -> -66689.03 | U21: ='Tennessee counties'!H59+'Tennessee counties'!H69+'Tennessee counties'!H52 -> 32578 | V21: =$V$2 -> 108093.61 | W21: =U21-V21 -> -75515.606
A22: 21 | B22: Hickman, Williamson, & Cheatham | C22: ='Tennessee counties'!B42+'Tennessee counties'!B95+'Tennessee counties'!B12 -> 52908 | D22: =$D$2 -> 61230.788 | E22: =C22-D22 -> -8322.7879 | F22: ='Tennessee counties'!C42+'Tennessee counties'!C95+'Tennessee counties'!C12 -> 51280 | G22: =$G$2 -> 66205.727 | H22: =F22-G22 -> -14925.727 | I22: ='Tennessee counties'!D42+'Tennessee counties'!D95+'Tennessee counties'!D12 -> 49664 | J22: =$J$2 -> 70845 | K22: =I22-J22 -> -21181 | L22: ='Tennessee counties'!E42+'Tennessee counties'!E95+'Tennessee counties'!E12 -> 45483 | M22: =$M$2 -> 79289.576 | N22: =L22-M22 -> -33806.576 | O22: ='Tennessee counties'!F42+'Tennessee counties'!F95+'Tennessee counties'!F12 -> 50021 | P22: =$P$2 -> 88358.818 | Q22: =O22-P22 -> -38337.818 | R22: ='Tennessee counties'!G42+'Tennessee counties'!G95+'Tennessee counties'!G12 -> 46827 | S22: =$S$2 -> 99749.03 | T22: =R22-S22 -> -52922.03 | U22: ='Tennessee counties'!H42+'Tennessee counties'!H95+'Tennessee counties'!H12 -> 46557 | V22: =$V$2 -> 108093.61 | W22: =U22-V22 -> -61536.606
A23: 22 | B23: Giles, Lawrence, & Wayne | C23: ='Tennessee counties'!B29+'Tennessee counties'!B51+'Tennessee counties'!B92 -> 61373 | D23: =$D$2 -> 61230.788 | E23: =C23-D23 -> 142.21212 | F23: ='Tennessee counties'!C29+'Tennessee counties'!C51+'Tennessee counties'!C92 -> 62260 | G23: =$G$2 -> 66205.727 | H23: =F23-G23 -> -3945.7273 | I23: ='Tennessee counties'!D29+'Tennessee counties'!D51+'Tennessee counties'!D92 -> 67418 | J23: =$J$2 -> 70845 | K23: =I23-J23 -> -3427 | L23: ='Tennessee counties'!E29+'Tennessee counties'!E51+'Tennessee counties'!E92 -> 66926 | M23: =$M$2 -> 79289.576 | N23: =L23-M23 -> -12363.576 | O23: ='Tennessee counties'!F29+'Tennessee counties'!F51+'Tennessee counties'!F92 -> 71604 | P23: =$P$2 -> 88358.818 | Q23: =O23-P23 -> -16754.818 | R23: ='Tennessee counties'!G29+'Tennessee counties'!G51+'Tennessee counties'!G92 -> 69643 | S23: =$S$2 -> 99749.03 | T23: =R23-S23 -> -30106.03 | U23: ='Tennessee counties'!H29+'Tennessee counties'!H51+'Tennessee counties'!H92 -> 62367 | V23: =$V$2 -> 108093.61 | W23: =U23-V23 -> -45726.606
A24: 23 | B24: Dickson, Humphreys, Houston, & Stewart | C24: ='Tennessee counties'!B23+'Tennessee counties'!B44+'Tennessee counties'!B43+'Tennessee counties'!B82 -> 53733 | D24: =$D$2 -> 61230.788 | E24: =C24-D24 -> -7497.7879 | F24: ='Tennessee counties'!C23+'Tennessee counties'!C44+'Tennessee counties'!C43+'Tennessee counties'!C82 -> 54947 | G24: =$G$2 -> 66205.727 | H24: =F24-G24 -> -11258.727 | I24: ='Tennessee counties'!D23+'Tennessee counties'!D44+'Tennessee counties'!D43+'Tennessee counties'!D82 -> 53700 | J24: =$J$2 -> 70845 | K24: =I24-J24 -> -17145 | L24: ='Tennessee counties'!E23+'Tennessee counties'!E44+'Tennessee counties'!E43+'Tennessee counties'!E82 -> 49363 | M24: =$M$2 -> 79289.576 | N24: =L24-M24 -> -29926.576 | O24: ='Tennessee counties'!F23+'Tennessee counties'!F44+'Tennessee counties'!F43+'Tennessee counties'!F82 -> 52120 | P24: =$P$2 -> 88358.818 | Q24: =O24-P24 -> -36238.818 | R24: ='Tennessee counties'!G23+'Tennessee counties'!G44+'Tennessee counties'!G43+'Tennessee counties'!G82 -> 44328 | S24: =$S$2 -> 99749.03 | T24: =R24-S24 -> -55421.03 | U24: ='Tennessee counties'!H23+'Tennessee counties'!H44+'Tennessee counties'!H43+'Tennessee counties'!H82 -> 42995 | V24: =$V$2 -> 108093.61 | W24: =U24-V24 -> -65098.606
A25: 24 | B25: Henry & Carroll | C25: ='Tennessee counties'!B41+'Tennessee counties'!B10 -> 48458 | D25: =$D$2 -> 61230.788 | E25: =C25-D25 -> -12772.788 | F25: ='Tennessee counties'!C41+'Tennessee counties'!C10 -> 49405 | G25: =$G$2 -> 66205.727 | H25: =F25-G25 -> -16800.727 | I25: ='Tennessee counties'!D41+'Tennessee counties'!D10 -> 51512 | J25: =$J$2 -> 70845 | K25: =I25-J25 -> -19333 | L25: ='Tennessee counties'!E41+'Tennessee counties'!E10 -> 52564 | M25: =$M$2 -> 79289.576 | N25: =L25-M25 -> -26725.576 | O25: ='Tennessee counties'!F41+'Tennessee counties'!F10 -> 51855 | P25: =$P$2 -> 88358.818 | Q25: =O25-P25 -> -36503.818 | R25: ='Tennessee counties'!G41+'Tennessee counties'!G10 -> 50381 | S25: =$S$2 -> 99749.03 | T25: =R25-S25 -> -49368.03 | U25: ='Tennessee counties'!H41+'Tennessee counties'!H10 -> 45751 | V25: =$V$2 -> 108093.61 | W25: =U25-V25 -> -62342.606
A26: 25 | B26: Madison, Henderson, & Chester | C26: ='Tennessee counties'!B56+'Tennessee counties'!B40+'Tennessee counties'!B13 -> 45773 | D26: =$D$2 -> 61230.788 | E26: =C26-D26 -> -15457.788 | F26: ='Tennessee counties'!C56+'Tennessee counties'!C40+'Tennessee counties'!C13 -> 42476 | G26: =$G$2 -> 66205.727 | H26: =F26-G26 -> -23729.727 | I26: ='Tennessee counties'!D56+'Tennessee counties'!D40+'Tennessee counties'!D13 -> 46455 | J26: =$J$2 -> 70845 | K26: =I26-J26 -> -24390 | L26: ='Tennessee counties'!E56+'Tennessee counties'!E40+'Tennessee counties'!E13 -> 48159 | M26: =$M$2 -> 79289.576 | N26: =L26-M26 -> -31130.576 | O26: ='Tennessee counties'!F56+'Tennessee counties'!F40+'Tennessee counties'!F13 -> 50768 | P26: =$P$2 -> 88358.818 | Q26: =O26-P26 -> -37590.818 | R26: ='Tennessee counties'!G56+'Tennessee counties'!G40+'Tennessee counties'!G13 -> 48712 | S26: =$S$2 -> 99749.03 | T26: =R26-S26 -> -51037.03 | U26: ='Tennessee counties'!H56+'Tennessee counties'!H40+'Tennessee counties'!H13 -> 43769 | V26: =$V$2 -> 108093.61 | W26: =U26-V26 -> -64324.606
A27: 26 | B27: Hardeman, McNairy, Hardin, Decatur, & Benton | C27: ='Tennessee counties'!B36+'Tennessee counties'!B61+'Tennessee counties'!B37+'Tennessee counties'!B21+'Tennessee counties'!B4 -> 107252 | D27: =$D$2 -> 61230.788 | E27: =C27-D27 -> 46021.212 | F27: ='Tennessee counties'!C36+'Tennessee counties'!C61+'Tennessee counties'!C37+'Tennessee counties'!C21+'Tennessee counties'!C4 -> 103533 | G27: =$G$2 -> 66205.727 | H27: =F27-G27 -> 37327.273 | I27: ='Tennessee counties'!D36+'Tennessee counties'!D61+'Tennessee counties'!D37+'Tennessee counties'!D21+'Tennessee counties'!D4 -> 97216 | J27: =$J$2 -> 70845 | K27: =I27-J27 -> 26371 | L27: ='Tennessee counties'!E36+'Tennessee counties'!E61+'Tennessee counties'!E37+'Tennessee counties'!E21+'Tennessee counties'!E4 -> 93765 | M27: =$M$2 -> 79289.576 | N27: =L27-M27 -> 14475.424 | O27: ='Tennessee counties'!F36+'Tennessee counties'!F61+'Tennessee counties'!F37+'Tennessee counties'!F21+'Tennessee counties'!F4 -> 103990 | P27: =$P$2 -> 88358.818 | Q27: =O27-P27 -> 15631.182 | R27: ='Tennessee counties'!G36+'Tennessee counties'!G61+'Tennessee counties'!G37+'Tennessee counties'!G21+'Tennessee counties'!G4 -> 101524 | S27: =$S$2 -> 99749.03 | T27: =R27-S27 -> 1774.9697 | U27: ='Tennessee counties'!H36+'Tennessee counties'!H61+'Tennessee counties'!H37+'Tennessee counties'!H21+'Tennessee counties'!H4 -> 99599 | V27: =$V$2 -> 108093.61 | W27: =U27-V27 -> -8494.6061
